<?xml version="1.0"?>

<robot name="susy" xmlns:xacro="http://www.ros.org/wiki/xacro">

    <xacro:include filename="$(find susy_description)/urdf/susy_gazebo.xacro"/>
    <xacro:include filename="$(find susy_description)/urdf/susy_ros2_control.xacro"/>

    <xacro:property name="PI" value="3.14159265359"/>

    <xacro:property name="Z" value="0.02"/>
    <!--value="0.04"/-->
    <xacro:property name="escala" value="${Z} ${Z} ${Z}"/>

    <link name="base_footprint"/>
    
    
    <link name="base_link">
        <!--inertial>
          <origin xyz="0.0 0.0 0.0" rpy="0.0 0.0 0.0"/>
          <mass value="0.1"/>
          <inertia ixx="0.0" ixy="0.0" ixz="0.0" iyy="0.0" iyz="0.0" izz="0.0"/>
        </inertial-->
        <inertial>
            <origin xyz="-0.034449 0.0047388 0.015024" rpy="0 0 0" />
            <mass value="0.010403" />
            <inertia
              ixx="7.888E-07"
              ixy="4.0447E-24"
              ixz="-4.6448E-24"
              iyy="1.1661E-06"
              iyz="1.6738E-24"
              izz="7.6385E-07" />
        </inertial>
        <visual>
            <origin xyz="${Z*-15.0} ${Z*15.0} ${Z*0.0}" rpy="${PI/2} 0.0 0.0"/>
            <geometry>
                <mesh filename="package://susy_description/3Dmodels/base_simple.STL" scale="${escala}"/>
            </geometry>
            <material name="white">
                <color rgba="1.0 1.0 1.0 1.0"/>
            </material>
        </visual>
        <collision>
            <origin xyz="${Z*-15.0} ${Z*15.0} ${Z*0.0}" rpy="0.0 0.0 0.0"/>
            <geometry>
                <mesh filename="package://susy_description/3Dmodels/base_simple.STL" scale="${escala}"/>
            </geometry>
        </collision>
    </link>
    <link name="base_alta">
        <inertial>
          <origin
            xyz="-0.00319040539219524 0.049220093924398 0.000981360360559142"
            rpy="0 0 0" />
          <mass
            value="0.0132287477004238" />
          <inertia
            ixx="1.6270779519678E-05"
            ixy="-3.45923665292277E-08"
            ixz="-5.71408335634743E-08"
            iyy="2.21760234097984E-06"
            iyz="-3.04167868780514E-07"
            izz="1.57245413987899E-05" />
        </inertial>
        <visual>
            <origin xyz="${Z*-17.5} ${Z*17.5} ${Z*0}" rpy="${PI/2} 0.0 0.0"/>
            <geometry>
                <mesh filename="package://susy_description/3Dmodels/base_alta.STL" scale="${escala}"/>
            </geometry>
            <material name="pink">
                <color rgba="1.0 0.47 0.733 1.0"/>
            </material>
        </visual>
        <collision>
            <origin xyz="${Z*-17.5} ${Z*17.5} ${Z*0}" rpy="${PI/2} 0.0 0.0"/>
            <geometry>
                <mesh filename="package://susy_description/3Dmodels/base_alta.STL" scale="${escala}"/>
            </geometry>
        </collision>
    </link>

    <link name="right_wheel">
        <!--inertial>
          <origin xyz="0.0 0.0 0.0" rpy="0.0 0.0 0.0"/>
          <mass value="0.1"/>
          <inertia ixx="0.0" ixy="0.0" ixz="0.0" iyy="0.0" iyz="0.0" izz="0.0"/>
        </inertial-->
        <inertial>
            <origin
            xyz="6.93889390390723E-18 0 -1.73472347597681E-18"
            rpy="0 0 0" />
            <mass
            value="5.31571052376292E-05" />
            <inertia
            ixx="2.65196676411871E-10"
            ixy="5.99809599461261E-27"
            ixz="-1.26034226898413E-27"
            iyy="1.45400341050665E-10"
            iyz="-4.05381273347173E-26"
            izz="1.45400341050665E-10" />
        </inertial>
        <visual>
            <origin xyz="${Z*0.0} ${Z*3.2} ${Z*-3.2}" rpy="${PI/2} 0.0 0.0"/>
            <geometry>
                <mesh filename="package://susy_description/3Dmodels/rueda.STL" scale="${escala}"/>
            </geometry>
            <material name="ar">
                <color rgba="1.0 1.0 1.0 1.0"/>
            </material>
        </visual>
        <collision>
            <origin xyz="${Z*0.0} ${Z*0.0} ${Z*0.0}" rpy="${PI/2} 0.0 0.0"/>
            <geometry>
                <sphere radius="${Z*3.2}"/>
            </geometry>
        </collision>
        <!--collision>
            <origin xyz="${Z*10.5} ${Z*3.2} ${Z*-3.2}" rpy="${PI/2} 0.0 0.0"/>
            <geometry>
                <mesh filename="package://susy_description/3Dmodels/rueda.STL" scale="${escala}"/>
            </geometry>
        </collision-->
    </link>

    <link name="left_wheel">
        <!--inertial>
          <origin xyz="0.0 0.0 0.0" rpy="0.0 0.0 0.0"/>
          <mass value="0.1"/>
          <inertia ixx="0.0" ixy="0.0" ixz="0.0" iyy="0.0" iyz="0.0" izz="0.0"/>
        </inertial-->
        <inertial>
        <origin
            xyz="-3.46944695195361E-18 0 1.73472347597681E-18"
            rpy="0 0 0" />
        <mass
            value="5.31571052376294E-05" />
        <inertia
            ixx="2.65196676411872E-10"
            ixy="7.18881747627078E-27"
            ixz="-2.71331529614589E-27"
            iyy="1.45400341050665E-10"
            iyz="-4.21932577051101E-26"
            izz="1.45400341050665E-10" />
        </inertial>
        <visual>
            <origin xyz="${Z*-1.7} ${Z*3.2} ${Z*-3.2}" rpy="${PI/2} 0.0 0.0"/>
            <geometry>
                <mesh filename="package://susy_description/3Dmodels/rueda.STL" scale="${escala}"/>
            </geometry>
            <material name="ar">
                <color rgba="1.0 1.0 1.0 1.0"/>
            </material>
        </visual>
        <collision>
            <origin xyz="${Z*0.0} ${Z*0} ${Z*0}" rpy="${PI/2} 0.0 0.0"/>
            <geometry>
                <sphere radius="${Z*3.2}"/>
            </geometry>
        </collision>
    </link>

    <link name="caster_front">
        <!--inertial>
          <origin xyz="0.0 0.0 0.0" rpy="0.0 0.0 0.0"/>
          <mass value="0.1"/>
          <inertia ixx="0.0" ixy="0.0" ixz="0.0" iyy="0.0" iyz="0.0" izz="0.0"/>
        </inertial-->
        <inertial>
          <origin
            xyz="0 0.00194107729719985 -3.46944695195361E-18"
            rpy="0 0 0" />
          <mass
            value="1.19568337316797E-05" />
          <inertia
            ixx="1.10150680331523E-11"
            ixy="1.84136831372096E-44"
            ixz="-1.70132457547993E-44"
            iyy="8.50890915412933E-12"
            iyz="9.91516005255474E-28"
            izz="1.10150680331523E-11" />
        </inertial>
        <visual>
            <origin xyz="0.0 0.0 ${Z*-3.2}" rpy="${PI/2} 0.0 0.0"/>
            <geometry>
                <mesh filename="package://susy_description/3Dmodels/caster_front.STL" scale="${escala}"/>
            </geometry>
            <material name="dark">
                <color rgba="0.1 0.1 0.1 1.0"/>
            </material>
        </visual>
        <collision>
            <origin xyz="0.0 0.0 ${Z*-2.5}" rpy="0.0 0.0 0.0"/>
            <geometry>
                <sphere radius="${Z*0.69}"/>
            </geometry>
        </collision>
    </link>


    <link name="caster_back">
        <!--inertial>
          <origin xyz="0.0 0.0 0.0" rpy="0.0 0.0 0.0"/>
          <mass value="0.1"/>
          <inertia ixx="0.0" ixy="0.0" ixz="0.0" iyy="0.0" iyz="0.0" izz="0.0"/>
        </inertial-->
        <inertial>
          <origin
            xyz="0 0.00194107729719985 -0.00124007338649024"
            rpy="0 0 0" />
          <mass
            value="1.19568337316797E-05" />
          <inertia
            ixx="1.10150680331523E-11"
            ixy="1.84136831372096E-44"
            ixz="-1.70132457547992E-44"
            iyy="8.50890915412933E-12"
            iyz="8.24536042386014E-28"
            izz="1.10150680331523E-11" />
        </inertial>
        <visual>
            <origin xyz="0.0 0.0 ${Z*-3.2}" rpy="${PI/2} 0.0 0.0"/>
            <geometry>
                <mesh filename="package://susy_description/3Dmodels/caster_front.STL" scale="${escala}"/>
            </geometry>
            <material name="dark">
                <color rgba="0.1 0.1 0.1 1.0"/>
            </material>
        </visual>
        <collision>
            <origin xyz="0.0 0.0 ${Z*-2.5}" rpy="0.0 0.0 0.0"/>
            <geometry>
                <sphere radius="${Z*0.69}"/>
            </geometry>
        </collision>
    </link>

    <link name="base_brazo">
        <inertial>
            <origin
                xyz="-0.00131190278884245 0.0013952763323219 -0.00100683541399575"
                rpy="0 0 0" />
            <mass
                value="0.000898428749668525" />
            <inertia
                ixx="3.77000106630414E-08"
                ixy="2.55848945742919E-09"
                ixz="-5.95710974441721E-09"
                iyy="7.06087018620749E-08"
                iyz="2.69437289142249E-09"
                izz="3.61921158112464E-08" />
        </inertial>
        <visual>
            <origin xyz="${Z*12.5} ${Z*12.5} ${Z*0}" rpy="${PI/2} 0.0 ${3.0*PI/2.0}"/>
            <geometry>
                <mesh filename="package://susy_description/3Dmodels/base_brazo.STL" scale="${escala}"/>
            </geometry>
            <material name="solidos">
                <color rgba="1.0 1.0 1.0 1.0"/>
            </material>
        </visual>
        <collision>
            <origin xyz="${Z*12.5} ${Z*12.5} ${Z*0}" rpy="${PI/2} 0.0 ${3.0*PI/2.0}"/>
            <geometry>
                <mesh filename="package://susy_description/3Dmodels/base_brazo.STL" scale="${escala}"/>
            </geometry>
        </collision>
    </link>

    <link name="ante_brazo">
        <inertial>
          <origin
            xyz="-0.000162761065659097 0.00249999999999999 -0.00125"
            rpy="0 0 0" />
          <mass
            value="0.000217146018366026" />
          <inertia
            ixx="5.79883389157145E-10"
            ixy="-1.60129883534209E-25"
            ixz="-3.32164714728325E-24"
            iyy="6.02133781017732E-09"
            iyz="1.04570281756909E-25"
            izz="6.37502743020319E-09" />
        </inertial>
        <visual>
            <origin xyz="${Z*0.0} ${Z*0.0} ${Z*0}" rpy="${PI/2} 0.0 ${3.0*PI/2.0}"/>
            <geometry>
                <mesh filename="package://susy_description/3Dmodels/empujar.STL" scale="${escala}"/>
            </geometry>
            <material name="solidos3">
                <color rgba="1.0 1.0 0.4 1.0"/>
            </material>
        </visual>
        <collision>
            <origin xyz="${Z*0.0} ${Z*0.0} ${Z*0}" rpy="${PI/2} 0.0 ${3.0*PI/2.0}"/>
            <geometry>
                <mesh filename="package://susy_description/3Dmodels/empujar.STL" scale="${escala}"/>
            </geometry>
        </collision>
    </link>

    <link name="garraL">
        <inertial>
          <origin
            xyz="-0.0362340963148376 -0.0150572708310525 0.036304075881177"
            rpy="0 0 0" />
          <mass
            value="0.0249807971751331" />
          <inertia
            ixx="3.66050263139615E-05"
            ixy="-1.07320912031314E-07"
            ixz="1.15336633081441E-06"
            iyy="3.61505056274145E-05"
            iyz="3.74952358099008E-07"
            izz="3.57812220103228E-06" />
        </inertial>
        <visual>
            <origin xyz="${Z*0.0} ${Z*0.0} ${Z*0}" rpy="${PI/2} 0.0 ${3.0*PI/2.0}"/>
            <geometry>
                <mesh filename="package://susy_description/3Dmodels/garra.STL" scale="${escala}"/>
            </geometry>
            <material name="solidos2">
                <color rgba="1.0 0.5 1.0 1.0"/>
            </material>
        </visual>
        <collision>
            <origin xyz="${Z*0.0} ${Z*0.0} ${Z*0}" rpy="${PI/2} 0.0 ${3.0*PI/2.0}"/>
            <geometry>
                <mesh filename="package://susy_description/3Dmodels/garra.STL" scale="${escala}"/>
            </geometry>
        </collision>
    </link>

    <link name="garraR">
        <inertial>
          <origin
            xyz="0.000499999999999997 0.0025 0.0025"
            rpy="0 0 0" />
          <mass
            value="2.5E-05" />
          <inertia
            ixx="1.04166666666666E-10"
            ixy="4.5188437401285E-27"
            ixz="6.46234853557053E-27"
            iyy="5.41666666666665E-11"
            iyz="-4.25179285499401E-26"
            izz="5.41666666666666E-11" />
        </inertial>
        <visual>
            <origin xyz="${Z*0.0} ${Z*0.0} ${Z*0}" rpy="${PI/2} 0.0 ${3.0*PI/2.0}"/>
            <geometry>
                <mesh filename="package://susy_description/3Dmodels/garra.STL" scale="${escala}"/>
            </geometry>
            <material name="solido4">
                <color rgba="0.5 1.0 1.0 1.0"/>
            </material>
        </visual>
        <collision>
            <origin xyz="${Z*0.0} ${Z*0.0} ${Z*0}" rpy="${PI/2} 0.0 ${3.0*PI/2.0}"/>
            <geometry>
                <mesh filename="package://susy_description/3Dmodels/garra.STL" scale="${escala}"/>
            </geometry>
        </collision>
    </link>

    <joint name="base_joint" type="fixed">
        <origin xyz="0.0 0.0 ${Z*3.2}" rpy="0.0 0.0 0.0"/>
        <parent link="base_footprint"/>
        <child link="base_link"/>
    </joint>

    <joint name="alta_joint" type="continuous">
        <origin xyz="${Z*0.0} ${Z*0.0} ${Z*15}" rpy="0.0 0.0 ${PI}"/>
        <parent link="base_link"/>
        <child link="base_alta"/>
        <axis xyz="0.0 0.0 1.0"/>
    </joint>

    <joint name="alta_brazo_joint" type="prismatic">
        <origin xyz="${Z*0.0} ${Z*0.0} ${Z*10.0}" rpy="0.0 0.0 ${PI}"/>
        <parent link="base_alta"/>
        <child link="base_brazo"/>
        <limit effort="1000.0" lower="0.0" upper="${Z*63.5}" velocity="0.5"/>
        <axis xyz="0.0 0.0 1.0"/>
    </joint>

    <joint name="ante_brazo_joint" type="prismatic">
        <origin xyz="${Z*0.0} ${Z*-9.0} ${Z*1.5}" rpy="0.0 0.0 ${PI}"/>
        <parent link="base_brazo"/>
        <child link="ante_brazo"/>
        <limit effort="1000.0" lower="0.0" upper="${Z*8.5}" velocity="0.5"/>
        <axis xyz="1.0 0.0 0.0"/>
    </joint>

    <joint name="garra_joint" type="prismatic">
        <origin xyz="${Z*0.0} ${Z*-1.0} ${Z*0.0}" rpy="0.0 0.0 ${PI}"/>
        <parent link="ante_brazo"/>
        <child link="garraL"/>
        <limit effort="1000.0" lower="0.0" upper="${Z*5.25}" velocity="0.5"/>
        <axis xyz="0.0 1.0 0.0"/>
    </joint>

    <joint name="garra_joint_mimic" type="prismatic">
        <origin xyz="${Z*0.0} ${Z*-12.5} ${Z*0.0}" rpy="0.0 0.0 ${PI}"/>
        <parent link="ante_brazo"/>
        <child link="garraR"/>
        <limit effort="1000.0" lower="0.0" upper="${Z*7.0}" velocity="0.5"/>
        <axis xyz="0.0 1.0 0.0"/>
        <mimic joint = "garra_joint" multiplier = "-1.0"/>
    </joint>

    <joint name="base_caster_front" type="fixed">
        <origin xyz="0.0 ${Z*13} ${Z*0}" rpy="0.0 0.0 0.0"/>
        <parent link="base_link"/>
        <child link="caster_front"/>
    </joint>

    <joint name="base_caster_back" type="fixed">
        <origin xyz="0.0 ${Z*-13} ${Z*0}" rpy="0.0 0.0 0.0"/>
        <parent link="base_link"/>
        <child link="caster_back"/>
    </joint>

    <joint name="base_right_wheel" type="continuous">
        <origin xyz="${Z*10.5} ${Z*0.0} ${Z*0.0}" rpy="0.0 0.0 0.0"/>
        <parent link="base_link"/>
        <child link="right_wheel"/>
        <axis xyz="-1.0 0.0 0.0"/>
    </joint>

    <joint name="base_left_wheel" type="continuous">
        <origin xyz="${Z*-10.5} ${Z*0.0} ${Z*0.0}" rpy="0.0 0.0 0.0"/>
        <parent link="base_link"/>
        <child link="left_wheel"/>
        <axis xyz="-1.0 0.0 0.0"/>
    </joint>

    <!--link name="laser_link">
        <inertial>
            <origin xyz="0.0 0.0 0.0" rpy="0.0 0.0 0.0"/>
            <mass value="0.0"/>
            <inertia ixx="0.0" ixy="0.0" ixz="0.0" iyy="0.0" iyz="0.0" izz="0.0"/>
        </inertial>
        <visual>
            <origin xyz = "${Z*0.0} ${Z*0.0} ${Z*0.0}" rpy="0 0 0"/>
            <geometry>
              <mesh filename="package://susy_description/3Dmodels/laser_link.STL" scale="${escala}"/>
            </geometry>
        </visual>
        <collision>
          <origin xyz = "${Z*0.0} ${Z*0.0} ${Z*0.0}" rpy="0 0 0"/>
          <geometry>
            <mesh filename="package://susy_description/3Dmodels/laser_link.STL" scale="${escala}"/>
          </geometry>
        </collision>
      </link>
    
      <joint name="lasert_joint" type="fixed">
          <parent link="base_alta"/>
          <child link="laser_link"/>
          <origin xyz="${Z*0.0} ${Z*0.0} ${Z*15.0}" rpy="0 0 ${PI}"/>
      </joint-->

</robot>